[META]
version=2.0
spawnOnBlockType=2
spawnSunlight=True
spawnDarkness=False
spawnWater=False
spawnLava=False
underFill=False
randomRotation=True
dig=True
tree=True
branch=False
rarity=10
collisionPercentage=0
spawnElevationMin=0
spawnElevationMax=100
spawnInBiome=Swampland
[DATA]
0,0,0:17.0
-5,0,0:18.1
5,0,0:18.1
0,5,0:18.1
0,-5,0:18.1
-4,4,0:18.1
-4,-4,0:18.1
4,-4,0:18.1
4,4,0:18.1
0,0,1:17.0
0,-5,1:18.1
-5,0,1:18.1
0,5,1:18.1
-4,4,1:18.1
-4,-4,1:18.1
4,-4,1:18.1
4,4,1:18.1
5,0,1:18.1
-6,0,1:18.1
0,-6,1:18.1
0,6,1:18.1
6,0,1:18.1
-3,-4,1:18.1
-4,-3,1:18.1
-4,3,1:18.1
-3,4,1:18.1
3,4,1:18.1
4,3,1:18.1
3,-4,1:18.1
4,-3,1:18.1
-1,-5,1:18.1
1,-5,1:18.1
5,-1,1:18.1
5,1,1:18.1
-1,5,1:18.1
1,5,1:18.1
-5,-1,1:18.1
-5,1,1:18.1
0,0,2:17.0
-4,4,2:18.1
-4,-4,2:18.1
4,-4,2:18.1
4,4,2:18.1
-5,0,2:18.1
0,-5,2:18.1
0,5,2:18.1
5,0,2:18.1
-6,0,2:18.1
-5,-4,2:18.1
-4,-5,2:18.1
0,-6,2:18.1
-1,-5,2:18.1
1,-5,2:18.1
4,-5,2:18.1
5,-4,2:18.1
5,-1,2:18.1
5,1,2:18.1
-5,4,2:18.1
-4,5,2:18.1
-5,-1,2:18.1
-5,1,2:18.1
-1,5,2:18.1
1,5,2:18.1
4,3,2:18.1
3,4,2:18.1
5,4,2:18.1
4,5,2:18.1
-3,-4,2:18.1
-4,-3,2:18.1
3,-4,2:18.1
4,-3,2:18.1
-4,3,2:18.1
-3,4,2:18.1
6,0,2:18.1
0,6,2:18.1
-4,-2,2:18.1
-2,-4,2:18.1
2,-4,2:18.1
4,-2,2:18.1
4,2,2:18.1
2,4,2:18.1
-2,4,2:18.1
-4,2,2:18.1
0,0,3:17.0
5,0,3:17.0
-5,0,3:17.0
0,5,3:17.0
0,-5,3:17.0
4,4,3:17.0
4,-4,3:17.0
-4,-4,3:17.0
-4,4,3:17.0
-6,0,3:18.1
0,6,3:18.1
-5,4,3:18.1
-4,5,3:18.1
-5,-4,3:18.1
-4,-5,3:18.1
4,-5,3:18.1
5,-4,3:18.1
4,5,3:18.1
5,4,3:18.1
6,0,3:18.1
5,-1,3:18.1
5,1,3:18.1
0,-6,3:18.1
-1,-5,3:18.1
1,-5,3:18.1
-1,5,3:18.1
1,5,3:18.1
-5,-1,3:18.1
-5,1,3:18.1
-4,-3,3:18.1
-4,-2,3:18.1
-4,2,3:18.1
-4,3,3:18.1
-3,4,3:18.1
-2,4,3:18.1
3,4,3:18.1
2,4,3:18.1
4,3,3:18.1
4,2,3:18.1
4,-2,3:18.1
4,-3,3:18.1
3,-4,3:18.1
2,-4,3:18.1
-2,-4,3:18.1
-3,-4,3:18.1
-4,-1,3:18.1
-4,0,3:18.1
-4,1,3:18.1
-1,-4,3:18.1
0,-4,3:18.1
1,-4,3:18.1
4,-1,3:18.1
4,0,3:18.1
4,1,3:18.1
1,4,3:18.1
0,4,3:18.1
-1,4,3:18.1
-3,3,3:18.1
-3,-3,3:18.1
3,-3,3:18.1
3,3,3:18.1
0,0,4:17.0
0,-4,4:17.0
-3,3,4:17.0
3,3,4:17.0
0,5,4:17.0
-4,-4,4:17.0
4,-4,4:17.0
4,0,4:17.0
-4,0,4:17.0
-3,0,4:17.0
-5,0,4:18.1
-5,-1,4:18.1
-6,0,4:18.1
-5,1,4:18.1
-4,2,4:18.1
-4,3,4:18.1
-4,4,4:18.1
-5,4,4:18.1
-4,5,4:18.1
-3,4,4:18.1
-2,4,4:18.1
-1,4,4:18.1
-1,5,4:18.1
0,6,4:18.1
1,5,4:18.1
0,4,4:18.1
1,4,4:18.1
2,4,4:18.1
3,4,4:18.1
4,5,4:18.1
4,4,4:18.1
5,4,4:18.1
4,3,4:18.1
4,2,4:18.1
4,1,4:18.1
5,-1,4:18.1
5,0,4:18.1
5,1,4:18.1
6,0,4:18.1
4,-1,4:18.1
4,-2,4:18.1
4,-3,4:18.1
4,-5,4:18.1
5,-4,4:18.1
3,-4,4:18.1
2,-4,4:18.1
1,-4,4:18.1
1,-5,4:18.1
0,-5,4:18.1
-1,-5,4:18.1
0,-6,4:18.1
-4,-5,4:18.1
-5,-4,4:18.1
-4,-3,4:18.1
-4,-2,4:18.1
-4,-1,4:18.1
-3,-4,4:18.1
-2,-4,4:18.1
-1,-4,4:18.1
-4,1,4:18.1
3,-3,4:18.1
-3,-3,4:18.1
0,0,5:17.0
0,-3,5:17.0
0,-1,5:17.0
-2,2,5:17.0
2,2,5:17.0
1,1,5:17.0
-3,-3,5:17.0
0,4,5:17.0
3,-3,5:17.0
-3,0,5:17.0
3,0,5:17.0
-1,0,5:17.0
-3,3,5:18.1
3,3,5:18.1
-5,-4,5:18.1
-4,-4,5:18.1
-4,-5,5:18.1
-5,-1,5:18.1
-5,0,5:18.1
-6,0,5:18.1
-5,1,5:18.1
-5,4,5:18.1
-4,4,5:18.1
-4,5,5:18.1
-1,5,5:18.1
0,5,5:18.1
1,5,5:18.1
0,6,5:18.1
4,5,5:18.1
4,4,5:18.1
5,4,5:18.1
5,1,5:18.1
5,0,5:18.1
5,-1,5:18.1
6,0,5:18.1
5,-4,5:18.1
4,-4,5:18.1
4,-5,5:18.1
0,-6,5:18.1
0,-5,5:18.1
-1,-5,5:18.1
1,-5,5:18.1
-3,-4,5:18.1
-2,-4,5:18.1
-1,-4,5:18.1
0,-4,5:18.1
1,-4,5:18.1
2,-4,5:18.1
3,-4,5:18.1
-4,-3,5:18.1
-4,-2,5:18.1
-4,-1,5:18.1
-4,0,5:18.1
-4,1,5:18.1
-4,2,5:18.1
-4,3,5:18.1
-3,4,5:18.1
-2,4,5:18.1
-1,4,5:18.1
1,4,5:18.1
2,4,5:18.1
3,4,5:18.1
4,3,5:18.1
4,2,5:18.1
4,1,5:18.1
4,0,5:18.1
4,-1,5:18.1
4,-2,5:18.1
4,-3,5:18.1
1,0,5:18.1
0,0,6:17.0
0,-2,6:17.0
-1,1,6:17.0
2,-2,6:17.0
-2,-2,6:17.0
0,3,6:17.0
-1,-1,6:17.0
-2,0,6:17.0
2,0,6:17.0
1,0,6:17.0
0,-5,6:17.0
-4,-4,6:17.0
-5,0,6:17.0
-4,4,6:17.0
0,5,6:17.0
5,0,6:17.0
4,4,6:17.0
4,-4,6:17.0
3,3,6:17.0
-2,2,6:17.0
-4,0,6:17.0
4,0,6:17.0
-5,-4,6:18.1
-4,-5,6:18.1
-6,0,6:18.1
-5,-1,6:18.1
-5,1,6:18.1
-5,4,6:18.1
-4,5,6:18.1
-1,5,6:18.1
0,6,6:18.1
1,5,6:18.1
4,5,6:18.1
5,4,6:18.1
6,0,6:18.1
5,-1,6:18.1
5,1,6:18.1
5,-4,6:18.1
4,-5,6:18.1
0,-6,6:18.1
-1,-5,6:18.1
1,-5,6:18.1
-4,-3,6:18.1
-4,-2,6:18.1
-4,-1,6:18.1
-4,1,6:18.1
-4,2,6:18.1
-4,3,6:18.1
-3,4,6:18.1
-2,4,6:18.1
-1,4,6:18.1
0,4,6:18.1
1,4,6:18.1
2,4,6:18.1
3,4,6:18.1
4,3,6:18.1
4,2,6:18.1
4,1,6:18.1
4,-1,6:18.1
4,-2,6:18.1
4,-3,6:18.1
3,-4,6:18.1
2,-4,6:18.1
1,-4,6:18.1
0,-4,6:18.1
-1,-4,6:18.1
-2,-4,6:18.1
-3,-4,6:18.1
-3,-2,6:18.1
-3,-3,6:18.1
-2,-3,6:18.1
-3,2,6:18.1
-3,3,6:18.1
-2,3,6:18.1
2,3,6:18.1
3,2,6:18.1
2,-3,6:18.1
3,-3,6:18.1
3,-2,6:18.1
0,0,7:17.0
0,2,7:17.0
1,-1,7:17.0
-3,-3,7:17.0
3,-3,7:17.0
0,4,7:17.0
-3,3,7:17.0
-4,-5,7:18.1
-4,-4,7:18.1
-5,-4,7:18.1
-4,-3,7:18.1
-4,-2,7:18.1
-4,-1,7:18.1
-4,0,7:18.1
-5,-1,7:18.1
-5,0,7:18.1
-6,0,7:18.1
-5,1,7:18.1
-4,1,7:18.1
-4,2,7:18.1
-4,3,7:18.1
-5,4,7:18.1
-4,4,7:18.1
-4,5,7:18.1
-3,4,7:18.1
-2,4,7:18.1
-1,4,7:18.1
-1,5,7:18.1
0,5,7:18.1
0,6,7:18.1
1,5,7:18.1
1,4,7:18.1
2,4,7:18.1
3,4,7:18.1
4,4,7:18.1
4,5,7:18.1
5,4,7:18.1
3,3,7:18.1
4,3,7:18.1
4,2,7:18.1
4,1,7:18.1
4,0,7:18.1
5,0,7:18.1
5,1,7:18.1
6,0,7:18.1
5,-1,7:18.1
4,-1,7:18.1
4,-2,7:18.1
4,-3,7:18.1
4,-4,7:18.1
4,-5,7:18.1
5,-4,7:18.1
3,-4,7:18.1
2,-4,7:18.1
1,-4,7:18.1
0,-4,7:18.1
-1,-4,7:18.1
-2,-4,7:18.1
-3,-4,7:18.1
-1,-5,7:18.1
0,-5,7:18.1
0,-6,7:18.1
1,-5,7:18.1
-3,-2,7:18.1
-3,-1,7:18.1
-2,-3,7:18.1
-1,-3,7:18.1
-2,-2,7:18.1
-3,1,7:18.1
-3,2,7:18.1
-2,3,7:18.1
-2,2,7:18.1
-1,3,7:18.1
1,3,7:18.1
2,3,7:18.1
2,2,7:18.1
3,2,7:18.1
3,1,7:18.1
1,-3,7:18.1
2,-3,7:18.1
2,-2,7:18.1
3,-2,7:18.1
3,-1,7:18.1
0,-3,7:18.1
-3,0,7:18.1
3,0,7:18.1
0,3,7:18.1
0,0,8:17.0
0,1,8:17.0
0,3,8:17.0
-2,-2,8:17.0
2,-2,8:17.0
-4,-4,8:18.1
-4,-3,8:18.1
-3,-2,8:18.1
-4,-2,8:18.1
-3,-4,8:18.1
-2,-4,8:18.1
-2,-3,8:18.1
-3,-3,8:18.1
-5,-1,8:18.1
-5,0,8:18.1
-5,1,8:18.1
-4,0,8:18.1
-4,1,8:18.1
-4,-1,8:18.1
-4,2,8:18.1
-4,3,8:18.1
-4,4,8:18.1
-3,4,8:18.1
-3,3,8:18.1
-2,4,8:18.1
-2,3,8:18.1
-3,2,8:18.1
-2,2,8:18.1
-2,1,8:18.1
-3,1,8:18.1
-3,0,8:18.1
-3,-1,8:18.1
-2,-1,8:18.1
-2,0,8:18.1
-1,4,8:18.1
-1,5,8:18.1
0,5,8:18.1
1,5,8:18.1
1,4,8:18.1
0,4,8:18.1
5,-1,8:18.1
5,0,8:18.1
5,1,8:18.1
4,2,8:18.1
4,3,8:18.1
4,4,8:18.1
3,4,8:18.1
2,4,8:18.1
3,3,8:18.1
3,2,8:18.1
2,2,8:18.1
2,3,8:18.1
1,3,8:18.1
-1,3,8:18.1
-1,2,8:18.1
-1,1,8:18.1
-1,0,8:18.1
-1,-1,8:18.1
0,2,8:18.1
1,2,8:18.1
1,1,8:18.1
2,1,8:18.1
3,1,8:18.1
4,1,8:18.1
3,0,8:18.1
2,0,8:18.1
1,0,8:18.1
4,0,8:18.1
4,-1,8:18.1
3,-1,8:18.1
2,-1,8:18.1
1,-1,8:18.1
-1,-5,8:18.1
0,-5,8:18.1
1,-5,8:18.1
-1,-4,8:18.1
0,-4,8:18.1
1,-4,8:18.1
1,-3,8:18.1
0,-3,8:18.1
-1,-3,8:18.1
-1,-2,8:18.1
0,-2,8:18.1
0,-1,8:18.1
1,-2,8:18.1
2,-4,8:18.1
3,-4,8:18.1
3,-3,8:18.1
4,-3,8:18.1
4,-4,8:18.1
2,-3,8:18.1
3,-2,8:18.1
4,-2,8:18.1
0,0,9:17.0
-1,-1,9:17.0
1,-1,9:17.0
-2,-1,9:18.1
-2,0,9:18.1
-2,1,9:18.1
-2,2,9:18.1
-1,2,9:18.1
0,2,9:18.1
1,2,9:18.1
2,2,9:18.1
2,1,9:18.1
2,0,9:18.1
2,-1,9:18.1
2,-2,9:18.1
1,-2,9:18.1
0,-2,9:18.1
-1,-2,9:18.1
-2,-2,9:18.1
-3,-2,9:18.1
-3,-1,9:18.1
-3,0,9:18.1
-3,1,9:18.1
-3,2,9:18.1
-2,3,9:18.1
-1,3,9:18.1
0,3,9:18.1
1,3,9:18.1
2,3,9:18.1
-3,3,9:18.1
-3,-3,9:18.1
-2,-3,9:18.1
-1,-3,9:18.1
0,-3,9:18.1
1,-3,9:18.1
2,-3,9:18.1
3,-3,9:18.1
3,-2,9:18.1
3,-1,9:18.1
3,0,9:18.1
3,1,9:18.1
3,2,9:18.1
3,3,9:18.1
4,-1,9:18.1
4,0,9:18.1
4,1,9:18.1
-4,-1,9:18.1
-4,0,9:18.1
-4,1,9:18.1
-1,-4,9:18.1
0,-4,9:18.1
1,-4,9:18.1
-1,4,9:18.1
0,4,9:18.1
1,4,9:18.1
-1,1,9:18.1
1,1,9:18.1
0,-1,9:18.1
-1,0,9:18.1
1,0,9:18.1
-1,0,10:18.1
-1,-1,10:18.1
0,-1,10:18.1
1,-1,10:18.1
1,0,10:18.1
0,0,10:18.1
0,1,10:18.1
1,1,10:18.1
-1,1,10:18.1
-2,-1,10:18.1
-2,0,10:18.1
-2,1,10:18.1
-1,-2,10:18.1
0,-2,10:18.1
1,-2,10:18.1
2,0,10:18.1
2,-1,10:18.1
2,1,10:18.1
-1,2,10:18.1
0,2,10:18.1
1,2,10:18.1
