[META]
version=2.0
spawnOnBlockType=88
spawnSunlight=True
spawnDarkness=True
spawnWater=False
spawnLava=False
underFill=False
randomRotation=True
dig=False
tree=False
branch=False
needsFoundation=True
rarity=70
collisionPercentage=0
spawnElevationMin=0
spawnElevationMax=128
spawnInBiome=Swampland
[DATA]
0,-2,0:17.0
-2,1,0:17.0
1,2,0:17.0
0,-1,1:17.0
-1,1,1:17.0
1,1,1:17.0
0,0,2:17.0
0,-1,2:17.0
-1,1,2:17.0
1,1,2:17.0
0,0,3:17.0
0,0,4:17.0
0,0,5:17.0
0,0,6:17.0
0,-1,6:18.1
-1,0,6:18.1
1,0,6:18.1
0,1,6:18.1
-1,-1,6:18.1
0,0,7:17.0
0,-3,7:18.1
0,-2,7:18.1
0,-1,7:18.1
-1,-1,7:18.1
-1,-2,7:18.1
1,-1,7:18.1
1,-2,7:18.1
2,-1,7:18.1
2,0,7:18.1
1,0,7:18.1
3,0,7:18.1
2,1,7:18.1
1,1,7:18.1
1,2,7:18.1
0,2,7:18.1
0,1,7:18.1
0,3,7:18.1
-1,2,7:18.1
-1,1,7:18.1
-1,0,7:18.1
-2,0,7:18.1
-3,0,7:18.1
-2,1,7:18.1
-2,-1,7:18.1
-2,-2,7:18.1
-1,-3,7:18.1
-3,-1,7:18.1
3,-1,7:18.1
3,1,7:18.1
2,-2,7:18.1
2,2,7:18.1
1,3,7:18.1
0,0,8:17.0
0,-2,8:18.1
0,-1,8:18.1
-1,-1,8:18.1
-1,0,8:18.1
-2,0,8:18.1
-1,1,8:18.1
0,1,8:18.1
0,2,8:18.1
1,1,8:18.1
1,0,8:18.1
1,-1,8:18.1
2,0,8:18.1
-1,-2,8:18.1
-2,-1,8:18.1
2,-1,8:18.1
2,1,8:18.1
1,-2,8:18.1
-1,-1,9:18.1
0,-1,9:18.1
1,-1,9:18.1
1,0,9:18.1
1,1,9:18.1
0,1,9:18.1
-1,1,9:18.1
-1,0,9:18.1
0,-2,9:18.1
2,0,9:18.1
0,-1,10:18.1
0,0,10:18.1
0,1,10:18.1
-1,0,10:18.1
1,0,10:18.1
1,-1,10:18.1
0,0,11:18.1
-3,1,-1:9
-2,0,-1:9
-2,2,-1:9
-2,1,-1:17.0
-1,0,-1:9
-1,-2,-1:9
0,-2,-1:17.0
1,-2,-1:9
0,-3,-1:9
1,0,-1:9
0,-1,-1:9
0,2,-1:9
1,2,-1:17.0
2,2,-1:9
1,3,-1:9
1,1,-1:88
0,1,-1:9
0,0,-1:9
1,-1,-1:88
-1,-1,-1:9
-1,1,-1:9
-1,2,-1:88
-4,1,-1:88
-3,2,-1:88
-2,3,-1:88
0,3,-1:88
1,4,-1:88
2,3,-1:88
3,2,-1:88
2,1,-1:88
2,0,-1:88
2,-2,-1:88
1,-3,-1:88
0,-4,-1:88
-1,-3,-1:88
-2,-2,-1:88
-2,-1,-1:88
-3,0,-1:88
