[META]
version=2.0
spawnOnBlockType=88
spawnSunlight=True
spawnDarkness=True
spawnWater=False
spawnLava=False
underFill=False
randomRotation=True
dig=False
tree=False
branch=False
needsFoundation=True
rarity=70
collisionPercentage=0
spawnElevationMin=0
spawnElevationMax=80
spawnInBiome=Swampland
[DATA]
0,0,0:17.0
-1,-2,0:17.0
2,-1,0:17.0
0,2,0:17.0
-1,-2,-1:17.0
2,-1,-1:17.0
0,2,-1:17.0
0,0,-1:17.0
-2,-2,-1:9
-1,-3,-1:9
0,-2,-1:88
0,-1,-1:9
-1,-1,-1:9
-1,0,-1:9
-1,1,-1:9
-1,2,-1:9
0,1,-1:9
1,2,-1:9
1,1,-1:9
1,0,-1:9
1,-1,-1:9
2,-2,-1:9
3,-1,-1:9
2,0,-1:9
4,-1,-1:88
3,0,-1:88
2,1,-1:88
2,2,-1:88
1,3,-1:88
0,3,-1:9
0,4,-1:88
-1,3,-1:88
-2,2,-1:88
-2,1,-1:88
-2,0,-1:88
-2,-1,-1:88
-3,-2,-1:88
-2,-3,-1:88
-1,-4,-1:88
0,-3,-1:88
1,-2,-1:88
2,-3,-1:88
3,-2,-1:88
0,1,1:17.0
-1,-1,1:17.0
1,-1,1:17.0
0,0,1:17.0
0,0,2:17.0
0,0,3:17.0
0,0,4:17.0
0,0,5:17.0
0,0,6:17.0
0,0,7:17.0
1,0,7:17.0
2,0,7:17.0
0,1,7:17.0
0,0,8:17.0
0,2,8:17.0
2,-1,8:17.0
0,-1,8:17.0
0,-2,8:17.0
-1,0,8:17.0
0,0,9:17.0
3,-1,9:17.0
0,2,9:17.0
-2,0,9:17.0
0,-3,9:17.0
0,4,9:17.0
3,-1,10:17.0
0,3,10:17.0
-3,0,10:17.0
0,-3,10:17.0
-3,1,11:17.0
1,-3,11:17.0
-2,-2,-2:88
-1,-3,-2:88
-1,-2,-2:88
-1,-1,-2:88
-1,0,-2:88
-1,1,-2:88
-1,2,-2:88
0,2,-2:88
0,3,-2:88
0,1,-2:88
0,0,-2:88
0,-1,-2:88
1,-1,-2:88
1,0,-2:88
1,1,-2:88
1,2,-2:88
2,0,-2:88
2,-1,-2:88
2,-2,-2:88
3,-1,-2:88
0,-2,-2:88
