[META]
version=2.0
spawnOnBlockType=88
spawnSunlight=True
spawnDarkness=True
spawnWater=False
spawnLava=False
underFill=False
randomRotation=True
dig=False
tree=True
branch=False
needsFoundation=True
rarity=70
collisionPercentage=0
spawnElevationMin=0
spawnElevationMax=128
spawnInBiome=Swampland
[DATA]
0,-1,0:17.0
1,1,0:17.0
-1,1,0:17.0
0,-1,-1:17.0
-1,1,-1:17.0
1,1,-1:17.0
0,-2,-1:88
-1,-1,-1:88
1,-1,-1:88
-1,0,-1:88
0,0,-1:88
1,0,-1:88
0,1,-1:88
-2,1,-1:88
0,2,-1:88
2,1,-1:88
1,2,-1:88
-1,2,-1:88
0,0,1:17.0
-1,0,1:17.0
-1,1,1:17.0
0,-1,1:17.0
1,0,1:17.0
1,1,1:17.0
0,0,2:17.0
0,0,3:17.0
0,0,4:17.0
0,-1,4:18.1
0,1,4:18.1
1,0,4:18.1
-1,0,4:18.1
0,0,5:17.0
0,-1,5:18.1
-1,0,5:18.1
1,0,5:18.1
0,1,5:18.1
-2,0,5:18.1
-1,-1,5:18.1
0,-2,5:18.1
1,-1,5:18.1
2,0,5:18.1
1,1,5:18.1
0,2,5:18.1
-1,1,5:18.1
0,-1,6:18.1
-1,0,6:18.1
0,1,6:18.1
1,0,6:18.1
0,0,6:17.0
0,0,7:18.1
-1,-1,7:18.1
-1,0,7:18.1
-1,1,7:18.1
0,1,7:18.1
1,1,7:18.1
1,0,7:18.1
1,-1,7:18.1
0,-1,7:18.1
0,-2,7:18.1
2,0,7:18.1
-2,0,7:18.1
0,2,7:18.1
0,-1,-2:88
-1,1,-2:88
1,1,-2:88
0,0,8:18.1
