[META]
version=2.0
spawnOnBlockType=2
spawnSunlight=True
spawnDarkness=False
spawnWater=False
spawnLava=False
underFill=False
randomRotation=True
dig=True
tree=True
branch=False
needsFoundation=True
rarity=100
collisionPercentage=2
spawnElevationMin=0
spawnElevationMax=128
spawnInBiome=All
[DATA]
0,0,0:17
1,0,0:17
0,1,0:17
1,1,0:17
0,0,1:17
1,0,1:17
0,1,1:17
1,1,1:17
0,0,2:17
1,0,2:17
0,1,2:17
1,1,2:17
0,0,3:17
1,0,3:17
0,1,3:17
1,1,3:17
0,0,4:17
1,0,4:17
0,1,4:17
1,1,4:17
0,0,5:17
1,0,5:17
0,1,5:17
1,1,5:17
0,0,6:17
1,0,6:17
0,1,6:17
1,1,6:17
0,0,7:17
1,0,7:17
0,1,7:17
1,1,7:17
0,0,8:17
1,0,8:17
0,1,8:17
1,1,8:17
0,0,9:17
1,0,9:17
0,1,9:17
1,1,9:17
-1,-3,10:18
0,-3,10:18
1,-3,10:18
2,-3,10:18
-2,-2,10:18
-1,-2,10:18
0,-2,10:18
1,-2,10:18
2,-2,10:18
3,-2,10:18
-3,-1,10:18
-2,-1,10:18
-1,-1,10:18
0,-1,10:18
1,-1,10:18
2,-1,10:18
3,-1,10:18
4,-1,10:18
-3,0,10:18
-2,0,10:18
-1,0,10:18
0,0,10:17
1,0,10:17
2,0,10:18
3,0,10:18
4,0,10:18
-3,1,10:18
-2,1,10:18
-1,1,10:18
0,1,10:17
1,1,10:17
2,1,10:18
3,1,10:18
4,1,10:18
-3,2,10:18
-2,2,10:18
-1,2,10:18
0,2,10:18
1,2,10:18
2,2,10:18
3,2,10:18
4,2,10:18
-2,3,10:18
-1,3,10:18
0,3,10:18
1,3,10:18
2,3,10:18
3,3,10:18
-1,4,10:18
0,4,10:18
1,4,10:18
2,4,10:18
-1,-2,11:18
0,-2,11:18
1,-2,11:18
2,-2,11:18
-2,-1,11:18
-1,-1,11:18
0,-1,11:18
1,-1,11:18
2,-1,11:18
3,-1,11:18
-2,0,11:18
-1,0,11:18
0,0,11:17
1,0,11:17
2,0,11:18
3,0,11:18
-2,1,11:18
-1,1,11:18
0,1,11:17
1,1,11:17
2,1,11:18
3,1,11:18
-2,2,11:18
-1,2,11:18
0,2,11:18
1,2,11:18
2,2,11:18
3,2,11:18
-1,3,11:18
0,3,11:18
1,3,11:18
2,3,11:18
-1,-1,12:18
0,-1,12:18
1,-1,12:18
2,-1,12:18
-1,0,12:18
0,0,12:17
1,0,12:17
2,0,12:18
-1,1,12:18
0,1,12:17
1,1,12:17
2,1,12:18
-1,2,12:18
0,2,12:18
1,2,12:18
2,2,12:18
-1,-3,13:18
0,-3,13:18
1,-3,13:18
2,-3,13:18
-2,-2,13:18
-1,-2,13:18
0,-2,13:18
1,-2,13:18
2,-2,13:18
3,-2,13:18
-3,-1,13:18
-2,-1,13:18
-1,-1,13:18
0,-1,13:18
1,-1,13:18
2,-1,13:18
3,-1,13:18
4,-1,13:18
-3,0,13:18
-2,0,13:18
-1,0,13:18
0,0,13:17
1,0,13:17
2,0,13:18
3,0,13:18
4,0,13:18
-3,1,13:18
-2,1,13:18
-1,1,13:18
0,1,13:17
1,1,13:17
2,1,13:18
3,1,13:18
4,1,13:18
-3,2,13:18
-2,2,13:18
-1,2,13:18
0,2,13:18
1,2,13:18
2,2,13:18
3,2,13:18
4,2,13:18
-2,3,13:18
-1,3,13:18
0,3,13:18
1,3,13:18
2,3,13:18
3,3,13:18
-1,4,13:18
0,4,13:18
1,4,13:18
2,4,13:18
-1,-2,14:18
0,-2,14:18
1,-2,14:18
2,-2,14:18
-2,-1,14:18
-1,-1,14:18
0,-1,14:18
1,-1,14:18
2,-1,14:18
3,-1,14:18
-2,0,14:18
-1,0,14:18
0,0,14:17
1,0,14:17
2,0,14:18
3,0,14:18
-2,1,14:18
-1,1,14:18
0,1,14:17
1,1,14:17
2,1,14:18
3,1,14:18
-2,2,14:18
-1,2,14:18
0,2,14:18
1,2,14:18
2,2,14:18
3,2,14:18
-1,3,14:18
0,3,14:18
1,3,14:18
2,3,14:18
-1,-1,15:18
0,-1,15:18
1,-1,15:18
2,-1,15:18
-1,0,15:18
0,0,15:17
1,0,15:17
2,0,15:18
-1,1,15:18
0,1,15:17
1,1,15:17
2,1,15:18
-1,2,15:18
0,2,15:18
1,2,15:18
2,2,15:18
-1,-3,16:18
0,-3,16:18
1,-3,16:18
2,-3,16:18
-2,-2,16:18
-1,-2,16:18
0,-2,16:18
1,-2,16:18
2,-2,16:18
3,-2,16:18
-3,-1,16:18
-2,-1,16:18
-1,-1,16:18
0,-1,16:18
1,-1,16:18
2,-1,16:18
3,-1,16:18
4,-1,16:18
-3,0,16:18
-2,0,16:18
-1,0,16:18
0,0,16:17
1,0,16:17
2,0,16:18
3,0,16:18
4,0,16:18
-3,1,16:18
-2,1,16:18
-1,1,16:18
0,1,16:17
1,1,16:17
2,1,16:18
3,1,16:18
4,1,16:18
-3,2,16:18
-2,2,16:18
-1,2,16:18
0,2,16:18
1,2,16:18
2,2,16:18
3,2,16:18
4,2,16:18
-2,3,16:18
-1,3,16:18
0,3,16:18
1,3,16:18
2,3,16:18
3,3,16:18
-1,4,16:18
0,4,16:18
1,4,16:18
2,4,16:18
-1,-2,17:18
0,-2,17:18
1,-2,17:18
2,-2,17:18
-2,-1,17:18
-1,-1,17:18
0,-1,17:18
1,-1,17:18
2,-1,17:18
3,-1,17:18
-2,0,17:18
-1,0,17:18
0,0,17:17
1,0,17:17
2,0,17:18
3,0,17:18
-2,1,17:18
-1,1,17:18
0,1,17:17
1,1,17:17
2,1,17:18
3,1,17:18
-2,2,17:18
-1,2,17:18
0,2,17:18
1,2,17:18
2,2,17:18
3,2,17:18
-1,3,17:18
0,3,17:18
1,3,17:18
2,3,17:18
-1,-1,18:18
0,-1,18:18
1,-1,18:18
2,-1,18:18
-1,0,18:18
0,0,18:17
1,0,18:17
2,0,18:18
-1,1,18:18
0,1,18:17
1,1,18:17
2,1,18:18
-1,2,18:18
0,2,18:18
1,2,18:18
2,2,18:18
-1,-3,19:18
0,-3,19:18
1,-3,19:18
2,-3,19:18
-2,-2,19:18
-1,-2,19:18
0,-2,19:18
1,-2,19:18
2,-2,19:18
3,-2,19:18
-3,-1,19:18
-2,-1,19:18
-1,-1,19:18
0,-1,19:18
1,-1,19:18
2,-1,19:18
3,-1,19:18
4,-1,19:18
-3,0,19:18
-2,0,19:18
-1,0,19:18
0,0,19:17
1,0,19:17
2,0,19:18
3,0,19:18
4,0,19:18
-3,1,19:18
-2,1,19:18
-1,1,19:18
0,1,19:17
1,1,19:17
2,1,19:18
3,1,19:18
4,1,19:18
-3,2,19:18
-2,2,19:18
-1,2,19:18
0,2,19:18
1,2,19:18
2,2,19:18
3,2,19:18
4,2,19:18
-2,3,19:18
-1,3,19:18
0,3,19:18
1,3,19:18
2,3,19:18
3,3,19:18
-1,4,19:18
0,4,19:18
1,4,19:18
2,4,19:18
-1,-2,20:18
0,-2,20:18
1,-2,20:18
2,-2,20:18
-2,-1,20:18
-1,-1,20:18
0,-1,20:18
1,-1,20:18
2,-1,20:18
3,-1,20:18
-2,0,20:18
-1,0,20:18
0,0,20:17
1,0,20:17
2,0,20:18
3,0,20:18
-2,1,20:18
-1,1,20:18
0,1,20:17
1,1,20:17
2,1,20:18
3,1,20:18
-2,2,20:18
-1,2,20:18
0,2,20:18
1,2,20:18
2,2,20:18
3,2,20:18
-1,3,20:18
0,3,20:18
1,3,20:18
2,3,20:18
-1,-1,21:18
0,-1,21:18
1,-1,21:18
2,-1,21:18
-1,0,21:18
0,0,21:17
1,0,21:17
2,0,21:18
-1,1,21:18
0,1,21:17
1,1,21:17
2,1,21:18
-1,2,21:18
0,2,21:18
1,2,21:18
2,2,21:18
-1,-3,22:18
0,-3,22:18
1,-3,22:18
2,-3,22:18
-2,-2,22:18
-1,-2,22:18
0,-2,22:18
1,-2,22:18
2,-2,22:18
3,-2,22:18
-3,-1,22:18
-2,-1,22:18
-1,-1,22:18
0,-1,22:18
1,-1,22:18
2,-1,22:18
3,-1,22:18
4,-1,22:18
-3,0,22:18
-2,0,22:18
-1,0,22:18
0,0,22:17
1,0,22:17
2,0,22:18
3,0,22:18
4,0,22:18
-3,1,22:18
-2,1,22:18
-1,1,22:18
0,1,22:17
1,1,22:17
2,1,22:18
3,1,22:18
4,1,22:18
-3,2,22:18
-2,2,22:18
-1,2,22:18
0,2,22:18
1,2,22:18
2,2,22:18
3,2,22:18
4,2,22:18
-2,3,22:18
-1,3,22:18
0,3,22:18
1,3,22:18
2,3,22:18
3,3,22:18
-1,4,22:18
0,4,22:18
1,4,22:18
2,4,22:18
-1,-2,23:18
0,-2,23:18
1,-2,23:18
2,-2,23:18
-2,-1,23:18
-1,-1,23:18
0,-1,23:18
1,-1,23:18
2,-1,23:18
3,-1,23:18
-2,0,23:18
-1,0,23:18
0,0,23:17
1,0,23:17
2,0,23:18
3,0,23:18
-2,1,23:18
-1,1,23:18
0,1,23:17
1,1,23:17
2,1,23:18
3,1,23:18
-2,2,23:18
-1,2,23:18
0,2,23:18
1,2,23:18
2,2,23:18
3,2,23:18
-1,3,23:18
0,3,23:18
1,3,23:18
2,3,23:18
-1,-1,24:18
0,-1,24:18
1,-1,24:18
2,-1,24:18
-1,0,24:18
0,0,24:17
1,0,24:17
2,0,24:18
-1,1,24:18
0,1,24:17
1,1,24:17
2,1,24:18
-1,2,24:18
0,2,24:18
1,2,24:18
2,2,24:18
-1,-3,25:18
0,-3,25:18
1,-3,25:18
2,-3,25:18
-2,-2,25:18
-1,-2,25:18
0,-2,25:18
1,-2,25:18
2,-2,25:18
3,-2,25:18
-3,-1,25:18
-2,-1,25:18
-1,-1,25:18
0,-1,25:18
1,-1,25:18
2,-1,25:18
3,-1,25:18
4,-1,25:18
-3,0,25:18
-2,0,25:18
-1,0,25:18
0,0,25:17
1,0,25:17
2,0,25:18
3,0,25:18
4,0,25:18
-3,1,25:18
-2,1,25:18
-1,1,25:18
0,1,25:17
1,1,25:17
2,1,25:18
3,1,25:18
4,1,25:18
-3,2,25:18
-2,2,25:18
-1,2,25:18
0,2,25:18
1,2,25:18
2,2,25:18
3,2,25:18
4,2,25:18
-2,3,25:18
-1,3,25:18
0,3,25:18
1,3,25:18
2,3,25:18
3,3,25:18
-1,4,25:18
0,4,25:18
1,4,25:18
2,4,25:18
-1,-2,26:18
0,-2,26:18
1,-2,26:18
2,-2,26:18
-2,-1,26:18
-1,-1,26:18
0,-1,26:18
1,-1,26:18
2,-1,26:18
3,-1,26:18
-2,0,26:18
-1,0,26:18
0,0,26:17
1,0,26:17
2,0,26:18
3,0,26:18
-2,1,26:18
-1,1,26:18
0,1,26:17
1,1,26:17
2,1,26:18
3,1,26:18
-2,2,26:18
-1,2,26:18
0,2,26:18
1,2,26:18
2,2,26:18
3,2,26:18
-1,3,26:18
0,3,26:18
1,3,26:18
2,3,26:18
-1,-1,27:18
0,-1,27:18
1,-1,27:18
2,-1,27:18
-1,0,27:18
0,0,27:17
1,0,27:17
2,0,27:18
-1,1,27:18
0,1,27:17
1,1,27:17
2,1,27:18
-1,2,27:18
0,2,27:18
1,2,27:18
2,2,27:18
-1,-3,28:18
0,-3,28:18
1,-3,28:18
2,-3,28:18
-2,-2,28:18
-1,-2,28:18
0,-2,28:18
1,-2,28:18
2,-2,28:18
3,-2,28:18
-3,-1,28:18
-2,-1,28:18
-1,-1,28:18
0,-1,28:18
1,-1,28:18
2,-1,28:18
3,-1,28:18
4,-1,28:18
-3,0,28:18
-2,0,28:18
-1,0,28:18
0,0,28:17
1,0,28:17
2,0,28:18
3,0,28:18
4,0,28:18
-3,1,28:18
-2,1,28:18
-1,1,28:18
0,1,28:17
1,1,28:17
2,1,28:18
3,1,28:18
4,1,28:18
-3,2,28:18
-2,2,28:18
-1,2,28:18
0,2,28:18
1,2,28:18
2,2,28:18
3,2,28:18
4,2,28:18
-2,3,28:18
-1,3,28:18
0,3,28:18
1,3,28:18
2,3,28:18
3,3,28:18
-1,4,28:18
0,4,28:18
1,4,28:18
2,4,28:18
-1,-2,29:18
0,-2,29:18
1,-2,29:18
2,-2,29:18
-2,-1,29:18
-1,-1,29:18
0,-1,29:18
1,-1,29:18
2,-1,29:18
3,-1,29:18
-2,0,29:18
-1,0,29:18
0,0,29:17
1,0,29:17
2,0,29:18
3,0,29:18
-2,1,29:18
-1,1,29:18
0,1,29:17
1,1,29:17
2,1,29:18
3,1,29:18
-2,2,29:18
-1,2,29:18
0,2,29:18
1,2,29:18
2,2,29:18
3,2,29:18
-1,3,29:18
0,3,29:18
1,3,29:18
2,3,29:18
-1,-2,30:18
0,-2,30:18
1,-2,30:18
2,-2,30:18
-2,-1,30:18
-1,-1,30:18
0,-1,30:18
1,-1,30:18
2,-1,30:18
3,-1,30:18
-2,0,30:18
-1,0,30:18
0,0,30:17
1,0,30:17
2,0,30:18
3,0,30:18
-2,1,30:18
-1,1,30:18
0,1,30:17
1,1,30:17
2,1,30:18
3,1,30:18
-2,2,30:18
-1,2,30:18
0,2,30:18
1,2,30:18
2,2,30:18
3,2,30:18
-1,3,30:18
0,3,30:18
1,3,30:18
2,3,30:18
-1,-1,31:18
0,-1,31:18
1,-1,31:18
2,-1,31:18
-1,0,31:18
0,0,31:18
1,0,31:18
2,0,31:18
-1,1,31:18
0,1,31:18
1,1,31:18
2,1,31:18
-1,2,31:18
0,2,31:18
1,2,31:18
2,2,31:18
0,-1,32:18
1,-1,32:18
-1,0,32:18
0,0,32:18
1,0,32:18
2,0,32:18
-1,1,32:18
0,1,32:18
1,1,32:18
2,1,32:18
0,2,32:18
1,2,32:18
0,0,33:18
1,0,33:18
0,1,33:18
1,1,33:18
0,0,34:18
1,0,34:18
0,1,34:18
1,1,34:18
