[META]
version=2.0
spawnOnBlockType=2
spawnSunlight=True
spawnDarkness=False
spawnWater=False
spawnLava=False
underFill=False
randomRotation=True
dig=True
tree=True
branch=False
needsFoundation=True
rarity=100
collisionPercentage=2
spawnElevationMin=0
spawnElevationMax=128
spawnInBiome=All
[DATA]
0,1,0:17
0,1,1:17
0,1,2:17
0,1,3:17
1,-1,4:17
1,0,4:17
-1,1,4:17
0,1,4:17
-2,-7,5:18
-2,-6,5:18
-1,-6,5:18
-3,-5,5:18
0,-5,5:18
0,-3,5:17
0,-2,5:17
3,-2,5:17
4,-2,5:18
2,-1,5:17
3,-1,5:17
5,-1,5:18
6,-1,5:18
-6,0,5:18
-5,0,5:18
-4,0,5:17
-3,0,5:17
4,0,5:17
5,0,5:18
6,0,5:18
7,0,5:18
-7,1,5:18
-6,1,5:18
-5,1,5:18
-2,1,5:17
4,1,5:18
5,1,5:18
-6,2,5:18
1,2,5:17
1,3,5:17
2,3,5:17
0,4,5:17
-2,6,5:18
-1,6,5:18
0,6,5:18
1,6,5:18
2,6,5:18
-2,7,5:18
1,7,5:18
2,7,5:18
-3,-6,6:18
-1,-6,6:18
0,-6,6:18
1,-6,6:18
-4,-5,6:18
-3,-5,6:17
-2,-5,6:18
-1,-5,6:18
0,-5,6:17
1,-5,6:18
2,-5,6:18
-3,-4,6:18
-2,-4,6:17
-1,-4,6:17
0,-4,6:18
1,-4,6:18
2,-4,6:18
3,-4,6:18
4,-4,6:18
-3,-3,6:18
2,-3,6:18
3,-3,6:18
4,-3,6:17
5,-3,6:18
-4,-2,6:18
4,-2,6:18
5,-2,6:18
-5,-1,6:18
-4,-1,6:17
-1,-1,6:17
4,-1,6:18
5,-1,6:18
-5,0,6:18
5,0,6:18
6,0,6:18
-6,1,6:18
-5,1,6:17
2,1,6:17
5,1,6:17
6,1,6:18
-6,2,6:18
-5,2,6:18
5,2,6:18
6,2,6:18
-5,3,6:18
-4,3,6:18
-3,3,6:17
-2,3,6:17
-1,3,6:17
4,3,6:18
5,3,6:18
-4,4,6:18
-3,4,6:18
3,4,6:17
4,4,6:17
5,4,6:18
-3,5,6:18
-2,5,6:18
-1,5,6:17
1,5,6:17
3,5,6:18
4,5,6:18
5,5,6:18
-3,6,6:18
-2,6,6:17
-1,6,6:18
0,6,6:18
1,6,6:17
2,6,6:18
3,6,6:18
-3,7,6:18
-2,7,6:18
-1,7,6:18
0,7,6:18
1,7,6:18
-3,-5,7:18
0,-5,7:18
-2,-4,7:18
-1,-4,7:18
0,-4,7:18
-2,-3,7:18
-1,-3,7:18
0,-3,7:18
1,-3,7:18
3,-3,7:18
4,-3,7:18
-3,-2,7:18
-2,-2,7:18
1,-2,7:18
2,-2,7:18
3,-2,7:18
4,-2,7:18
-4,-1,7:18
-3,-1,7:18
-2,-1,7:18
3,-1,7:18
-4,0,7:18
-3,0,7:18
0,0,7:17
3,0,7:17
4,0,7:18
-5,1,7:18
-4,1,7:18
-3,1,7:18
3,1,7:18
4,1,7:18
5,1,7:18
-4,2,7:18
-3,2,7:18
1,2,7:17
2,2,7:18
3,2,7:18
4,2,7:18
-3,3,7:18
-2,3,7:18
-1,3,7:18
1,3,7:18
3,3,7:18
4,3,7:18
-2,4,7:18
-1,4,7:18
0,4,7:18
1,4,7:18
2,4,7:18
3,4,7:18
4,4,7:18
-1,5,7:18
0,5,7:18
1,5,7:18
2,5,7:18
-2,6,7:18
1,6,7:18
-1,-2,8:18
0,-2,8:18
-1,-1,8:18
0,-1,8:18
1,-1,8:18
2,-1,8:18
-2,0,8:18
-1,0,8:18
0,0,8:18
1,0,8:18
2,0,8:18
3,0,8:18
-2,1,8:18
-1,1,8:18
0,1,8:17
1,1,8:18
2,1,8:18
-2,2,8:18
-1,2,8:18
0,2,8:18
1,2,8:18
2,2,8:18
-2,3,8:18
-1,3,8:18
0,3,8:18
1,3,8:18
2,3,8:18
0,0,9:18
1,0,9:18
0,1,9:18
1,1,9:18
-1,2,9:18
0,2,9:18
