[META]
version=2.0
spawnOnBlockType=2
spawnSunlight=True
spawnDarkness=True
spawnWater=False
spawnLava=False
underFill=False
randomRotation=True
dig=False
tree=True
branch=False
needsFoundation=True
rarity=10
collisionPercentage=0
spawnElevationMin=0
spawnElevationMax=100
spawnInBiome=Savanna,Shrubland
[DATA]
0,0,0:17.0
0,0,1:17.0
-1,0,1:17.0
0,-1,1:17.0
1,0,1:17.0
0,1,1:17.0
-2,0,2:17.0
2,0,2:17.0
0,-2,2:17.0
0,2,2:17.0
0,0,2:17.0
1,-1,2:17.0
-1,-1,2:17.0
-1,1,2:17.0
1,1,2:17.0
-2,-1,3:17.0
-1,-2,3:17.0
1,-2,3:17.0
2,-1,3:17.0
2,1,3:17.0
1,2,3:17.0
-1,2,3:17.0
0,0,3:17.0
-2,1,3:17.0
0,-1,3:17.0
0,1,3:17.0
-1,0,3:17.0
1,0,3:17.0
-1,-1,3:18.2
-1,1,3:18.2
1,1,3:18.2
1,-1,3:18.2
0,-2,3:18.2
-2,0,3:18.2
0,2,3:18.2
2,0,3:18.2
2,0,4:17.0
0,2,4:17.0
-2,0,4:17.0
0,-2,4:17.0
0,0,4:17.0
-1,-1,4:17.0
-1,1,4:17.0
1,1,4:17.0
1,-1,4:17.0
0,-1,4:18.2
-1,0,4:18.2
0,1,4:18.2
1,0,4:18.2
-1,-2,4:18.2
-2,-1,4:18.2
-2,1,4:18.2
-1,2,4:18.2
1,2,4:18.2
2,1,4:18.2
2,-1,4:18.2
1,-2,4:18.2
-1,-3,4:18.2
-3,-1,4:18.2
-3,1,4:18.2
-1,3,4:18.2
1,3,4:18.2
3,1,4:18.2
3,-1,4:18.2
1,-3,4:18.2
-1,0,5:17.0
0,-1,5:17.0
0,0,5:17.0
0,1,5:17.0
1,0,5:17.0
-1,-2,5:17.0
-2,-1,5:17.0
1,-2,5:17.0
2,-1,5:17.0
2,1,5:17.0
1,2,5:17.0
-1,2,5:17.0
-2,1,5:17.0
-1,-1,5:18.2
1,-1,5:18.2
1,1,5:18.2
-1,1,5:18.2
2,0,5:18.2
-2,0,5:18.2
0,-2,5:18.2
0,2,5:18.2
0,-3,5:18.2
3,0,5:18.2
-3,0,5:18.2
0,3,5:18.2
0,-1,6:18.2
-1,-1,6:17.0
-1,0,6:18.2
0,1,6:18.2
1,0,6:18.2
-2,1,6:18.2
-1,2,6:18.2
1,2,6:18.2
2,1,6:18.2
2,-1,6:18.2
1,-2,6:18.2
-1,-2,6:18.2
-2,-1,6:18.2
-1,1,6:17.0
1,1,6:17.0
1,-1,6:17.0
0,0,6:17.0
-2,0,6:17.0
0,-2,6:17.0
0,2,6:17.0
2,0,6:17.0
-1,-3,6:18.2
1,-3,6:18.2
3,-1,6:18.2
3,1,6:18.2
-1,3,6:18.2
-3,1,6:18.2
-3,-1,6:18.2
1,3,6:18.2
-2,0,7:18.2
-1,-1,7:18.2
0,-2,7:18.2
0,0,7:18.2
1,-1,7:18.2
2,0,7:18.2
1,1,7:18.2
0,2,7:18.2
-1,1,7:18.2
0,1,7:18.2
-1,0,7:18.2
0,-1,7:18.2
1,0,7:18.2
