[META]
version=2.0
spawnOnBlockType=2
spawnSunlight=True
spawnDarkness=True
spawnWater=False
spawnLava=False
underFill=False
randomRotation=True
dig=False
tree=False
branch=False
needsFoundation=True
rarity=1
collisionPercentage=0
spawnElevationMin=0
spawnElevationMax=110
spawnInBiome=Forest,Plains,Shrubland,Swampland
[DATA]
-3,0,0:39
-3,-1,0:39
-2,-2,0:39
-1,-3,0:39
0,-3,0:39
2,-3,0:39
2,-2,0:39
3,-2,0:39
3,-1,0:39
3,0,0:39
4,0,0:39
4,1,0:39
3,2,0:39
2,2,0:39
2,3,0:39
0,3,0:39
-1,3,0:39
-3,2,0:39
-3,1,0:39
-3,-2,0:39
-2,-3,0:39
-1,-4,0:39
0,-4,0:39
2,-4,0:39
1,-4,0:39
3,-3,0:39
4,-1,0:39
3,3,0:39
4,2,0:39
-2,3,0:39
-4,0,0:39
-2,1,0:39
-2,-1,0:39
1,4,0:39
0,4,0:39
2,4,0:39
-1,4,0:39
-1,2,0:39
-1,4,-1:2
-3,2,-1:2
-3,1,-1:2
-2,-2,-1:2
-2,-1,-1:2
-2,0,-1:2
-3,0,-1:2
-2,-3,-1:2
-3,-1,-1:2
-1,-3,-1:2
-1,-2,-1:2
1,-3,-1:2
0,-3,-1:2
2,-3,-1:2
2,-2,-1:2
1,-2,-1:2
3,-1,-1:2
2,-1,-1:2
3,0,-1:2
2,0,-1:2
3,2,-1:2
2,2,-1:2
1,2,-1:2
1,1,-1:2
1,0,-1:2
3,1,-1:2
0,2,-1:2
-1,1,-1:2
-1,0,-1:2
0,0,-1:2
0,-1,-1:2
1,-1,-1:2
2,1,-1:2
0,1,-1:2
-1,-1,-1:2
0,-2,-1:2
-1,2,-1:2
-2,2,-1:2
-2,1,-1:2
2,3,-1:2
1,3,-1:2
0,3,-1:2
-1,3,-1:2
3,3,-1:2
0,4,-1:2
-2,3,-1:2
-4,0,-1:2
-3,-2,-1:2
-1,-4,-1:2
0,-4,-1:2
1,-4,-1:2
2,-4,-1:2
3,-2,-1:2
3,-3,-1:2
4,-1,-1:2
4,0,-1:2
4,1,-1:2
4,2,-1:2
2,4,-1:2
1,4,-1:2
-2,-3,-2:3
-1,-3,-2:3
-1,-4,-2:3
0,-4,-2:3
1,-4,-2:3
2,-4,-2:3
2,-3,-2:3
3,-3,-2:3
3,-2,-2:3
3,-1,-2:3
4,-1,-2:3
4,0,-2:3
4,1,-2:3
4,2,-2:3
0,4,-2:3
-1,4,-2:3
-1,3,-2:3
-2,3,-2:3
-3,2,-2:3
-4,0,-2:3
-3,-1,-2:3
-3,-2,-2:3
-2,-2,-2:3
-3,0,-2:3
-3,1,-2:3
-2,0,-2:3
-2,-1,-2:3
-1,-1,-2:3
0,-2,-2:3
0,-3,-2:3
-1,-2,-2:3
1,-3,-2:3
1,-2,-2:3
0,-1,-2:3
2,-2,-2:3
2,-1,-2:3
1,-1,-2:3
0,0,-2:3
-1,0,-2:3
1,0,-2:3
2,0,-2:3
2,1,-2:3
1,1,-2:3
0,1,-2:3
-1,1,-2:3
-2,1,-2:3
3,1,-2:3
2,2,-2:3
1,2,-2:3
0,2,-2:3
3,0,-2:3
-1,2,-2:3
-2,2,-2:3
3,2,-2:3
3,3,-2:3
2,3,-2:3
1,3,-2:3
1,4,-2:3
0,3,-2:3
2,4,-2:3
