[META]
version=2.0
spawnOnBlockType=88
spawnSunlight=True
spawnDarkness=True
spawnWater=False
spawnLava=False
underFill=False
randomRotation=True
dig=False
tree=True
branch=False
needsFoundation=True
rarity=90
collisionPercentage=0
spawnElevationMin=0
spawnElevationMax=100
spawnInBiome=Swampland
[DATA]
0,0,0:17.0
-1,-2,0:17.0
2,-1,0:17.0
0,2,0:17.0
-1,-2,-1:17.0
2,-1,-1:17.0
0,2,-1:17.0
0,0,-1:17.0
-2,-2,-1:9
-1,-3,-1:9
0,-2,-1:88
0,-1,-1:9
-1,-1,-1:9
-1,0,-1:9
-1,1,-1:9
-1,2,-1:9
0,1,-1:9
1,2,-1:9
1,1,-1:9
1,0,-1:9
1,-1,-1:9
2,-2,-1:9
3,-1,-1:9
2,0,-1:9
4,-1,-1:88
3,0,-1:88
2,1,-1:88
2,2,-1:88
1,3,-1:88
0,3,-1:9
0,4,-1:88
-1,3,-1:88
-2,2,-1:88
-2,1,-1:88
-2,0,-1:88
-2,-1,-1:88
-3,-2,-1:88
-2,-3,-1:88
-1,-4,-1:88
0,-3,-1:88
1,-2,-1:88
2,-3,-1:88
3,-2,-1:88
0,1,1:17.0
-1,-1,1:17.0
1,-1,1:17.0
0,0,1:17.0
0,0,2:17.0
0,0,3:17.0
0,0,4:17.0
0,0,5:17.0
0,0,6:17.0
0,0,7:17.0
1,0,7:17.0
2,0,7:17.0
0,1,7:17.0
0,0,8:17.0
0,2,8:17.0
2,-1,8:17.0
0,-1,8:17.0
0,-2,8:17.0
-1,0,8:17.0
-1,-1,8:18.0
1,-2,8:18.0
0,-3,8:18.0
-1,-2,8:18.0
1,-1,8:18.0
3,-1,8:18.0
2,-2,8:18.0
2,0,8:18.0
1,0,8:18.0
0,1,8:18.0
-2,0,8:18.0
-1,1,8:18.0
-1,2,8:18.0
0,3,8:18.0
1,1,8:18.0
1,2,8:18.0
0,0,9:17.0
3,-1,9:17.0
0,2,9:17.0
-2,0,9:17.0
0,-3,9:17.0
0,4,9:17.0
-1,-1,9:18.0
1,-1,9:18.0
1,-2,9:18.0
2,-1,9:18.0
1,2,9:18.0
-1,0,9:18.0
-1,-3,9:18.0
0,-4,9:18.0
1,-4,9:18.0
1,-3,9:18.0
-1,-2,9:18.0
-2,-1,9:18.0
-3,0,9:18.0
-2,1,9:18.0
2,-2,9:18.0
3,-2,9:18.0
2,0,9:18.0
3,0,9:18.0
4,-1,9:18.0
1,0,9:18.0
-1,1,9:18.0
0,1,9:18.0
-1,2,9:18.0
0,3,9:18.0
1,1,9:18.0
2,1,9:18.0
1,3,9:18.0
-1,3,9:18.0
0,5,9:18.0
-1,4,9:18.0
1,4,9:18.0
-2,2,9:18.0
3,-1,10:17.0
0,3,10:17.0
-3,0,10:17.0
0,-3,10:17.0
0,0,10:17.0
-3,1,10:18.0
1,-3,10:18.0
2,-1,10:18.0
3,-2,10:18.0
5,-1,10:18.0
3,0,10:18.0
4,-1,10:18.0
0,2,10:18.0
-1,3,10:18.0
0,4,10:18.0
1,3,10:18.0
0,-4,10:18.0
-1,-3,10:18.0
0,-2,10:18.0
-4,0,10:18.0
-3,-1,10:18.0
-2,0,10:18.0
-1,0,10:18.0
0,-1,10:18.0
0,1,10:18.0
1,0,10:18.0
1,-1,10:18.0
1,-2,10:18.0
2,-2,10:18.0
1,1,10:18.0
2,0,10:18.0
1,2,10:18.0
2,1,10:18.0
-1,2,10:18.0
-1,1,10:18.0
-2,1,10:18.0
-2,-1,10:18.0
-1,-1,10:18.0
-1,-2,10:18.0
-2,-2,10:18.0
-2,2,10:18.0
2,2,10:18.0
4,0,10:18.0
3,1,10:18.0
2,-3,10:18.0
1,-4,10:18.0
2,-4,10:18.0
3,-3,10:18.0
1,-5,10:18.0
0,-5,10:18.0
-1,-4,10:18.0
-2,-3,10:18.0
-3,-2,10:18.0
-4,-1,10:18.0
-5,0,10:18.0
-4,1,10:18.0
-3,2,10:18.0
-3,1,11:17.0
1,-3,11:17.0
-4,1,11:18.0
-3,2,11:18.0
-2,1,11:18.0
1,-4,11:18.0
2,-3,11:18.0
1,-2,11:18.0
0,-3,11:18.0
-3,0,11:18.0
0,3,11:18.0
3,-1,11:18.0
0,0,11:18.0
0,-1,11:18.0
0,-2,11:18.0
1,-1,11:18.0
2,-1,11:18.0
2,-2,11:18.0
0,1,11:18.0
0,2,11:18.0
-1,0,11:18.0
-2,0,11:18.0
-1,1,11:18.0
-2,2,11:18.0
-1,-1,11:18.0
-2,-1,11:18.0
-1,-2,11:18.0
1,0,11:18.0
1,1,11:18.0
2,0,11:18.0
-1,2,11:18.0
1,2,11:18.0
2,1,11:18.0
-2,-2,11:18.0
-2,-2,-2:88
-1,-3,-2:88
-1,-2,-2:88
-1,-1,-2:88
-1,0,-2:88
-1,1,-2:88
-1,2,-2:88
0,2,-2:88
0,3,-2:88
0,1,-2:88
0,0,-2:88
0,-1,-2:88
1,-1,-2:88
1,0,-2:88
1,1,-2:88
1,2,-2:88
2,0,-2:88
2,-1,-2:88
2,-2,-2:88
3,-1,-2:88
0,-2,-2:88
-3,1,12:18.0
1,-3,12:18.0
-2,1,12:18.0
1,-2,12:18.0
1,-1,12:18.0
0,-1,12:18.0
0,-2,12:18.0
-1,0,12:18.0
-1,1,12:18.0
-2,0,12:18.0
0,0,12:18.0
-1,-1,12:18.0
